<?xml version='1.0'?>

<robot name="mark2" xmlns:xacro="http://www.ros.org/wiki/xacro">

    <link name="world"></link>

    <joint name="joint_n" type="floating">
        <origin xyz="0.0 0.0 0.2" rpy="0.0 0.0 0.0"/>
        <parent link="world"/>
        <child link="chassis"/>
    </joint>

    <link name="chassis">
        <inertial>
            <mass value="1.5"/>
            <origin xyz="0.0 0.0 0.0" rpy=" 0 0 0"/>
            <inertia
                ixx="0.00625" ixy="0" ixz="0"
                iyy="0.00625" iyz="0"
                izz="0.01"
            />
        </inertial>

        <collision name='chassis_collision'>
            <origin xyz="0.0 0.0 0.0" rpy=" 0 0 0"/>
            <geometry>
            <box size="0.2000 0.2000 0.1000"/>
            </geometry>
        </collision>

        <visual name='chassis_visual'>
            <origin xyz="0.0 0.0 0.0" rpy=" 0 0 0"/>
            <geometry>
            <box size="0.2000 0.2000 0.1000"/>
            </geometry>
        </visual>
    </link>

    <joint name="joint_1" type="revolute">
        <origin xyz="0.0 -0.1012 0.0" rpy="0.0 0.0 0.0"/>
        <parent link="chassis"/>
        <child link="right_leg_rocker"/>
        <axis xyz="0.0 1.0 0.0"/>
        <limit lower="-1.0" upper="1.0" effort="1.0" velocity="1.0"/>
    </joint>

    <link name="right_leg_rocker">

        <!-- visual /-->
        <visual name="r_up_part_visual">
            <geometry>
                <box size="0.2195 0.0254 0.0254"/>
            </geometry>
            <origin rpy="0 0 0" xyz="0.0 0.0 0.0"/>
        </visual>
        <visual name="r_down_part_visual">
            <geometry>
                <box size="0.173 0.0254 0.0254"/>
            </geometry>
            <origin rpy="0 -1.1659 0" xyz="-0.1436 0.0 -0.0807"/>
        </visual>
        <visual name="r_front_part_visual">
            <geometry>
                <box size="0.09741 0.0254 0.0254"/>
            </geometry>
            <origin rpy="0 1.1522 0" xyz="0.1295 0.0 -0.0445"/>
        </visual>
        

        <!-- collision /-->
        <collision name="r_up_part_collision">
            <geometry>
                <box size="0.2195 0.0254 0.0254"/>
            </geometry>
            <origin rpy="0 0 0" xyz="0.0 0.0 0.0"/>
        </collision>
        <collision name="r_down_part_collision">
            <geometry>
                <box size="0.173 0.0254 0.0254"/>
            </geometry>
            <origin rpy="0 -1.1659 0" xyz="-0.1436 0.0 -0.0807"/>
        </collision>
        <collision name="r_front_part_collision">
            <geometry>
                <box size="0.09741 0.0254 0.0254"/>
            </geometry>
            <origin rpy="0 1.1522 0" xyz="0.1295 0.0 -0.0445"/>
        </collision>
        
        <inertial>
            <mass value="1"/>
            <origin xyz="0.0 0.0 0.0" rpy=" 0 0 0"/>
            <inertia
                ixx="0.001" ixy="0" ixz="0"
                iyy="0.001" iyz="0"
                izz="0.001"
            />
        </inertial>

    </link>

    <joint name="joint_2" type="revolute">
        <origin xyz="0.0 0.1012 0.0" rpy="0.0 0.0 0.0"/>
        <parent link="chassis"/>
        <child link="left_leg_rocker"/>
        <axis xyz="0.0 1.0 0.0"/>
        <limit lower="-1.0" upper="1.0" effort="1.0" velocity="1.0"/>
    </joint>

    <link name="left_leg_rocker">

        <!-- visual /-->
        <visual name="l_up_part_visual">
            <geometry>
                <box size="0.2195 0.0254 0.0254"/>
            </geometry>
            <origin rpy="0 0 0" xyz="0.0 0.0 0.0"/>
        </visual>
        <visual name="l_down_part_visual">
            <geometry>
                <box size="0.173 0.0254 0.0254"/>
            </geometry>
            <origin rpy="0 -1.1659 0" xyz="-0.1436 0.0 -0.0807"/>
        </visual>
        <visual name="l_front_part_visual">
            <geometry>
                <box size="0.09741 0.0254 0.0254"/>
            </geometry>
            <origin rpy="0 1.1522 0" xyz="0.1295 0.0 -0.0445"/>
        </visual>
        

        <!-- collision /-->
        <collision name="l_up_part_collision">
            <geometry>
                <box size="0.2195 0.0254 0.0254"/>
            </geometry>
            <origin rpy="0 0 0" xyz="0.0 0.0 0.0"/>
        </collision>
        <collision name="l_down_part_collision">
            <geometry>
                <box size="0.173 0.0254 0.0254"/>
            </geometry>
            <origin rpy="0 -1.1659 0" xyz="-0.1436 0.0 -0.0807"/>
        </collision>
        <collision name="l_front_part_collision">
            <geometry>
                <box size="0.09741 0.0254 0.0254"/>
            </geometry>
            <origin rpy="0 1.1522 0" xyz="0.1295 0.0 -0.0445"/>
        </collision>
        
        <inertial>
            <mass value="1"/>
            <origin xyz="0.0 0.0 0.0" rpy=" 0 0 0"/>
            <inertia
                ixx="0.001" ixy="0" ixz="0"
                iyy="0.001" iyz="0"
                izz="0.001"
            />
        </inertial>

    </link>

    <joint name="joint_3" type="revolute">
        <origin rpy="0 0 0" xyz="0.1493 0.0 -0.089"/>
        <parent link="right_leg_rocker"/>
        <child link="right_leg_boogie"/>
        <axis xyz="0.0 1.0 0.0"/>
        <limit lower="-1.0" upper="1.0" effort="1.0" velocity="1.0"/>
    </joint>

    <link name="right_leg_boogie">

        <!-- visual /-->
        <visual name="r_base_visual">
            <geometry>
                <box size="0.200 0.0254 0.0254"/>
            </geometry>
            <origin rpy="0 0 0" xyz="0.0 0.0 0.0"/>
        </visual>
        <visual name="r_front_visual">
            <geometry>
                <box size="0.0254 0.0254 0.0695"/>
            </geometry>
            <origin rpy="0 0 0" xyz="0.1 0.0 -0.03475"/>
        </visual>
        <visual name="r_back_visual">
            <geometry>
                <box size="0.0254 0.0254 0.0695"/>
            </geometry>
            <origin rpy="0 0 0" xyz="-0.1 0.0 -0.03475"/>
        </visual>

        <!-- collision /-->
        
        <collision name="r_base_collision">
            <geometry>
                <box size="0.200 0.0254 0.0254"/>
            </geometry>
            <origin rpy="0 0 0" xyz="0.0 0.0 0.0"/>
        </collision>
        <collision name="r_front_collision">
            <geometry>
                <box size="0.0254 0.0254 0.0695"/>
            </geometry>
            <origin rpy="0 0 0" xyz="0.1 0.0 -0.03475"/>
        </collision>
        <collision name="r_back_collision">
            <geometry>
                <box size="0.0254 0.0254 0.0695"/>
            </geometry>
            <origin rpy="0 0 0" xyz="-0.1 0.0 -0.03475"/>
        </collision>

        <inertial>
        <mass value="0.01"/>
        <origin rpy="0 0 0" xyz="0.0 0.0 0.0"/>
        <inertia
            ixx="0.001" ixy="0" ixz="0"
            iyy="0.001" iyz="0"
            izz="0.001"
        />
        </inertial>

    </link>

    <joint name="joint_4" type="revolute">
        <origin rpy="0 0 0" xyz="0.1493 0.0 -0.089"/>
        <parent link="left_leg_rocker"/>
        <child link="left_leg_boogie"/>
        <axis xyz="0.0 1.0 0.0"/>
        <limit lower="-1.0" upper="1.0" effort="1.0" velocity="1.0"/>
    </joint>

    <link name="left_leg_boogie">

        <!-- visual /-->
        <visual name="l_base_visual">
            <geometry>
                <box size="0.200 0.0254 0.0254"/>
            </geometry>
            <origin rpy="0 0 0" xyz="0.0 0.0 0.0"/>
        </visual>
        <visual name="l_front_visual">
            <geometry>
                <box size="0.0254 0.0254 0.0695"/>
            </geometry>
            <origin rpy="0 0 0" xyz="0.1 0.0 -0.03475"/>
        </visual>
        <visual name="l_back_visual">
            <geometry>
                <box size="0.0254 0.0254 0.0695"/>
            </geometry>
            <origin rpy="0 0 0" xyz="-0.1 0.0 -0.03475"/>
        </visual>

        <!-- collision /-->
        
        <collision name="l_base_collision">
            <geometry>
                <box size="0.200 0.0254 0.0254"/>
            </geometry>
            <origin rpy="0 0 0" xyz="0.0 0.0 0.0"/>
        </collision>
        <collision name="l_front_collision">
            <geometry>
                <box size="0.0254 0.0254 0.0695"/>
            </geometry>
            <origin rpy="0 0 0" xyz="0.1 0.0 -0.03475"/>
        </collision>
        <collision name="l_back_collision">
            <geometry>
                <box size="0.0254 0.0254 0.0695"/>
            </geometry>
            <origin rpy="0 0 0" xyz="-0.1 0.0 -0.03475"/>
        </collision>

        <inertial>
        <mass value="0.01"/>
        <origin rpy="0 0 0" xyz="0.0 0.0 0.0"/>
        <inertia
            ixx="0.001" ixy="0" ixz="0"
            iyy="0.001" iyz="0"
            izz="0.001"
        />
        </inertial>

    </link>
    
    <joint name="joint_5" type="continuous">
        <origin xyz="0.1 -0.0377 -0.0695" rpy="0.0 1.5707 0.0"/>
        <parent link="right_leg_boogie"/>
        <child link="right_wheel_front"/>
        <axis xyz="0.0 1.0 0.0"/>
        <limit effort="100.0" velocity="4.0"/>
    </joint>

    <link name="right_wheel_front">

        <visual name="right_wheel_front_visual">
            <origin rpy="1.5707 0.0 0.0" xyz="0.0 0.0 0.0"/>
            <geometry>
                <cylinder length="0.0500" radius="0.0400"/>
            </geometry>
        </visual>

        <collision name="right_wheel_front_collision">
            <origin rpy="1.5707 0.0 0.0" xyz="0.0 0.0 0.0"/>
            <geometry>
                <cylinder length="0.0500" radius="0.0400"/>
            </geometry>
        </collision>
        <inertial>
            <mass value="0.0001"/>
            <origin xyz="0.2990 0.1954 0.2118" rpy=" 0 0 0"/>
            <inertia
                ixx="0.0001" ixy="0" ixz="0"
                iyy="0.0001" iyz="0"
                izz="0.0001"
            />
        </inertial>

    </link>

    <joint name="joint_6" type="continuous">
        <origin xyz="-0.1 -0.0377 -0.0695" rpy="0.0 1.5707 0.0"/>
        <parent link="right_leg_boogie"/>
        <child link="right_wheel_medium"/>
        <axis xyz="0.0 1.0 0.0"/>
        <limit effort="1.0" velocity="4.0"/>
    </joint>

    <link name="right_wheel_medium">

        <visual name="right_wheel_front_visual">
            <origin rpy="1.5707 0.0 0.0" xyz="0.0 0.0 0.0"/>
            <geometry>
                <cylinder length="0.0500" radius="0.0400"/>
            </geometry>
        </visual>

        <collision name="right_wheel_front_collision">
            <origin rpy="1.5707 0.0 0.0" xyz="0.0 0.0 0.0"/>
            <geometry>
                <cylinder length="0.0500" radius="0.0400"/>
            </geometry>
        </collision>
        <inertial>
            <mass value="0.0001"/>
            <origin xyz="0.2990 0.1954 0.2118" rpy=" 0 0 0"/>
            <inertia
                ixx="0.0001" ixy="0" ixz="0"
                iyy="0.0001" iyz="0"
                izz="0.0001"
            />
        </inertial>

    </link>

    <joint name="joint_7" type="continuous">
        <origin xyz="-0.1776 -0.0377 -0.1586" rpy="0.0 1.5707 0.0"/>
        <parent link="right_leg_rocker"/>
        <child link="right_wheel_back"/>
        <axis xyz="0.0 1.0 0.0"/>
        <limit effort="1.0" velocity="4.0"/>
    </joint>

    <link name="right_wheel_back">

        <visual name="right_wheel_front_visual">
            <origin rpy="1.5707 0.0 0.0" xyz="0.0 0.0 0.0"/>
            <geometry>
                <cylinder length="0.0500" radius="0.0400"/>
            </geometry>
        </visual>

        <collision name="right_wheel_front_collision">
            <origin rpy="1.5707 0.0 0.0" xyz="0.0 0.0 0.0"/>
            <geometry>
                <cylinder length="0.0500" radius="0.0400"/>
            </geometry>
        </collision>
        <inertial>
            <mass value="0.0001"/>
            <origin xyz="0.2990 0.1954 0.2118" rpy=" 0 0 0"/>
            <inertia
                ixx="0.0001" ixy="0" ixz="0"
                iyy="0.0001" iyz="0"
                izz="0.0001"
            />
        </inertial>

    </link>

    <joint name="joint_8" type="continuous">
        <origin xyz="0.1 0.0377 -0.0695" rpy="0.0 1.5707 0.0"/>
        <parent link="left_leg_boogie"/>
        <child link="left_wheel_front"/>
        <axis xyz="0.0 1.0 0.0"/>
        <limit effort="100.0" velocity="4.0"/>
    </joint>

    <link name="left_wheel_front">

        <visual name="left_wheel_front_visual">
            <origin rpy="1.5707 0.0 0.0" xyz="0.0 0.0 0.0"/>
            <geometry>
                <cylinder length="0.0500" radius="0.0400"/>
            </geometry>
        </visual>

        <collision name="left_wheel_front_collision">
            <origin rpy="1.5707 0.0 0.0" xyz="0.0 0.0 0.0"/>
            <geometry>
                <cylinder length="0.0500" radius="0.0400"/>
            </geometry>
        </collision>
        <inertial>
            <mass value="0.0001"/>
            <origin xyz="0.2990 0.1954 0.2118" rpy=" 0 0 0"/>
            <inertia
                ixx="0.0001" ixy="0" ixz="0"
                iyy="0.0001" iyz="0"
                izz="0.0001"
            />
        </inertial>

    </link>

    <joint name="joint_9" type="continuous">
        <origin xyz="-0.1 0.0377 -0.0695" rpy="0.0 1.5707 0.0"/>
        <parent link="left_leg_boogie"/>
        <child link="left_wheel_medium"/>
        <axis xyz="0.0 1.0 0.0"/>
        <limit effort="1.0" velocity="4.0"/>
    </joint>

    <link name="left_wheel_medium">

        <visual name="right_wheel_front_visual">
            <origin rpy="1.5707 0.0 0.0" xyz="0.0 0.0 0.0"/>
            <geometry>
                <cylinder length="0.0500" radius="0.0400"/>
            </geometry>
        </visual>

        <collision name="right_wheel_front_collision">
            <origin rpy="1.5707 0.0 0.0" xyz="0.0 0.0 0.0"/>
            <geometry>
                <cylinder length="0.0500" radius="0.0400"/>
            </geometry>
        </collision>
        <inertial>
            <mass value="0.0001"/>
            <origin xyz="0.2990 0.1954 0.2118" rpy=" 0 0 0"/>
            <inertia
                ixx="0.0001" ixy="0" ixz="0"
                iyy="0.0001" iyz="0"
                izz="0.0001"
            />
        </inertial>

    </link>

    <joint name="joint_10" type="continuous">
        <origin xyz="-0.1776 0.0377 -0.1586" rpy="0.0 1.5707 0.0"/>
        <parent link="left_leg_rocker"/>
        <child link="left_wheel_back"/>
        <axis xyz="0.0 1.0 0.0"/>
        <limit effort="1.0" velocity="4.0"/>
    </joint>

    <link name="left_wheel_back">       

        <visual name="right_wheel_front_visual">
            <origin rpy="1.5707 0.0 0.0" xyz="0.0 0.0 0.0"/>
            <geometry>
                <cylinder length="0.0500" radius="0.0400"/>
            </geometry>
        </visual>

        <collision name="right_wheel_front_collision">
            <origin rpy="1.5707 0.0 0.0" xyz="0.0 0.0 0.0"/>
            <geometry>
                <cylinder length="0.0500" radius="0.0400"/>
            </geometry>
        </collision>
        <inertial>
            <mass value="0.0001"/>
            <origin xyz="0.2990 0.1954 0.2118" rpy=" 0 0 0"/>
            <inertia
                ixx="0.0001" ixy="0" ixz="0"
                iyy="0.0001" iyz="0"
                izz="0.0001"
            />
        </inertial>

    </link>
    
    <!-- differential -->

    <joint name="joint_11" type="fixed">
        <origin xyz="0.0 0.1012 0.08" rpy="0.0 0.0 0.0"/>
        <parent link="right_leg_rocker"/>
        <child link="diff"/>
    </joint>

    <link name="diff">

        <visual name="">
            <origin xyz="0.0 0.0 0.0" rpy="0.0 0.0 0.0"/>
            <geometry>
                <box size="0.01 0.22 0.01"/>
            </geometry>
        </visual>

        <visual name="">
            <origin xyz="0.0 0.105 -0.04" rpy="0.0 0.0 0.0"/>
            <geometry>
                <box size="0.01 0.01 0.08"/>
            </geometry>
        </visual>

        <visual name="">
            <origin xyz="0.0 -0.105 -0.04" rpy="0.0 0.0 0.0"/>
            <geometry>
                <box size="0.01 0.01 0.08"/>
            </geometry>
        </visual>

        <collision>
            <origin xyz="0.0 0.0 0.0" rpy="0.0 0.0 0.0"/>
            <geometry>
                <box size="0.01 0.22 0.01"/>
            </geometry>
        </collision>

        <collision>
            <origin xyz="0.0 0.105 -0.04" rpy="0.0 0.0 0.0"/>
            <geometry>
                <box size="0.01 0.01 0.08"/>
            </geometry>
        </collision>

        <collision>
            <origin xyz="0.0 -0.105 -0.04" rpy="0.0 0.0 0.0"/>
            <geometry>
                <box size="0.01 0.01 0.08"/>
            </geometry>
        </collision>

        <inertial>
            <origin xyz="0.0 0.0 0.0" rpy="0.0 0.0 0.0"/>
            <mass value="0.001"/>
            <inertia ixx="0.001" ixy="0.0" ixz="0.0" iyy="0.001" iyz="0.0" izz="0.001"/>
        </inertial>
    </link>

    <!-- Transmission -->

    <transmission name="tran1">
        <type>transmission_interface/SimpleTransmission</type>
        <joint name="joint_5">
            <hardwareInterface>hardware_interface/VelocityJointInterface</hardwareInterface>
        </joint>
        <actuator name="Wheel_RF">
            <mechanicalReduction>1</mechanicalReduction>
        </actuator>
    </transmission>

    <transmission name="tran2">
        <type>transmission_interface/SimpleTransmission</type>
        <joint name="joint_6">
            <hardwareInterface>hardware_interface/VelocityJointInterface</hardwareInterface>
        </joint>
        <actuator name="Wheel_RM">
            <mechanicalReduction>1</mechanicalReduction>
        </actuator>
    </transmission>

    <transmission name="tran3">
        <type>transmission_interface/SimpleTransmission</type>
        <joint name="joint_7">
            <hardwareInterface>hardware_interface/VelocityJointInterface</hardwareInterface>
        </joint>
        <actuator name="Wheel_RB">
            <mechanicalReduction>1</mechanicalReduction>
        </actuator>
    </transmission>

    <transmission name="tran4">
        <type>transmission_interface/SimpleTransmission</type>
        <joint name="joint_8">
            <hardwareInterface>hardware_interface/VelocityJointInterface</hardwareInterface>
        </joint>
        <actuator name="Wheel_LF">
            <mechanicalReduction>1</mechanicalReduction>
        </actuator>
    </transmission>

    <transmission name="tran5">
        <type>transmission_interface/SimpleTransmission</type>
        <joint name="joint_9">
            <hardwareInterface>hardware_interface/VelocityJointInterface</hardwareInterface>
        </joint>
        <actuator name="Wheel_LM">
            <mechanicalReduction>1</mechanicalReduction>
        </actuator>
    </transmission>

    <transmission name="tran6">
        <type>transmission_interface/SimpleTransmission</type>
        <joint name="joint_10">
            <hardwareInterface>hardware_interface/VelocityJointInterface</hardwareInterface>
        </joint>
        <actuator name="Wheel_LB">
            <mechanicalReduction>1</mechanicalReduction>
        </actuator>
    </transmission>

    <!-- Plugins -->

    <gazebo>
        <plugin name="gazebo_ros_control" filename="libgazebo_ros_control.so">
            <robotNamespace>/</robotNamespace>
        </plugin>
    </gazebo>

    <gazebo reference="chassis">
        <material>Gazebo/Gray</material>
    </gazebo>

    <gazebo reference="right_wheel_front">
        <material>Gazebo/Black</material>
    </gazebo>

    <gazebo reference="right_wheel_medium">
        <material>Gazebo/Blue</material>
    </gazebo>

    <gazebo reference="right_wheel_back">
        <material>Gazebo/Black</material>
    </gazebo>

    <gazebo reference="left_wheel_front">
        <material>Gazebo/Black</material>
    </gazebo>

    <gazebo reference="left_wheel_medium">
        <material>Gazebo/Blue</material>
    </gazebo>

    <gazebo reference="left_wheel_back">
        <material>Gazebo/Black</material>
    </gazebo>

</robot>