<?xml version='1.0'?>

<robot name="mark2" xmlns:xacro="http://www.ros.org/wiki/xacro">

    <link name="world"></link>

    <joint name="joint_n" type="fixed">
        <origin xyz="0.0 0.0 0.0" rpy="0.0 0.0 0.0"/>
        <parent link="world"/>
        <child link="chassis"/>
    </joint>


        <!-- Chassis, caja de control /-->
    <link name="chassis">
        <inertial>
            <mass value="4"/>
            <origin xyz="0.2990 0.1954 0.2118" rpy=" 0 0 0"/>
            <inertia
                ixx="0.0001" ixy="0" ixz="0"
                iyy="0.0001" iyz="0"
                izz="0.0001"
            />
        </inertial>

        <collision name='chassis_collision'>
            <origin xyz="0.299 0.1954 0.2118" rpy=" 0 0 0"/>
            <geometry>
            <box size="0.2000 0.2000 0.1000"/>
            </geometry>
        </collision>

        <visual name='chassis_visual'>
            <origin xyz="0.299 0.1954 0.2118" rpy=" 0 0 0"/>
            <geometry>
            <box size="0.2000 0.200 0.1000"/>
            </geometry>
        </visual>
    </link>

    <joint name="joint_1" type="revolute">
        <origin xyz="0.0 0.0 0.0" rpy="0.0 0.0 0.0"/>
        <parent link="chassis"/>
        <child link="right_leg_rocker"/>
        <axis xyz="0.0 1.0 0.0"/>
        <limit lower="0.0" upper="1.0" effort="1.0" velocity="1.0"/>
    </joint>

    <link name="right_leg_rocker">
        <inertial>
            <origin xyz="0.0 0.0 0.0" rpy="0.0 0.0 0.0"/>
            <mass value="1.0"/>
            <inertia ixx="0.0" ixy="0.0" ixz="0.0" iyy="0.0" iyz="0.0" izz="0.0"/>
        </inertial>
        <visual name="">
            <origin xyz="0.0 0.0 0.0" rpy="0.0 0.0 0.0"/>
            <geometry>
                <box size="0.0 0.0 0.0"/>
            </geometry>
            <material name="">
                <color rgba="1.0 0.0 0.0 1.0"/>
                <texture filename=""/>
            </material>
        </visual>
        <collision>
            <origin xyz="0.0 0.0 0.0" rpy="0.0 0.0 0.0"/>
            <geometry>
                <box size="0.0 0.0 0.0"/>
            </geometry>
        </collision>
    </link>


</robot>